Workbook

Sheet Full Spreadsheet
A1: States | B1: Targeted Business Defintion | C1: State Agency(s) for Program(s) | D1: Year | E1: Total HUB Goal | F1: Goal Type (spending or participation) | G1: Total HUB Spending Utilization | H1: Total Annual Spending (if available) | I1: Success (%)
A2: Alabama | B2: Disadvantaged business enterprise or DBE means a for-profit small business concern— That is at least 51 percent owned by one or more individuals who are both socially and economically disadvantaged or, in the case of a corporation, in which 51 percent of the stock is owned by one or more such individuals; and Whose management and daily business operations are controlled by one or more of the socially and economically disadvantaged individuals who own it. | C2: Alabama Department of Transportation | D2: FY 2023 | E2: 0.0865 | F2: Participation | G2: 0.0761 | I2: =G2/E2 -> 0.87976879
A3: Alaska | B3: The eligibility requirements for certification as a Disadvantaged Business Enterprise (DBE) are detailed in Title 49, Part 26, of the Code of Federal Regulations (CFR). Business Status: The applicant firm must be an existing "for profit" business. It must also meet the federal definition of a small business based on its primary NAICS code, as described by the Small Business Administration (SBA), and must not exceed the Size Standards Exit Site icon in annual gross receipts. Social and Economic Disadvantage: A disadvantaged owner must be a U.S. citizen (or resident alien) and meet the federal definition of socially and economically disadvantaged as defined in 49 CFR 26.67 Exit Site icon. Individuals who can demonstrate social and economic disadvantage on an individual basis may also qualify. Business Ownership: Disadvantaged owners must hold at least 51% ownership in the firm and must control the day-to-day operation and management of the business. Professional License: When a firm's primary line of work requires a professional license, the disadvantaged owner must hold the license. Personal Net Worth: The Personal Net Worth of a disadvantaged owner cannot exceed $2.047 million. Ownership of Resources: A DBE firm must not rely on other individuals or businesses for its employees, equipment, or other resources. Other Business Involvement: DBE owners cannot engage in outside employment or other business interests that conflict with their management and control of the applicant firm. | C3: Alaska Department of Transportation & Public Facilities | D3: FY 2021-2023 | E3: 0.0525 | F3: Spending | G3: 0.1603 | I3: =G3/E3 -> 3.0533333
A4: Arizona | B4: A firm must be a minority or woman-owned business or owned by a majority owner who can demonstrate social and economic disadvantage. The disadvantaged owner must own at least 51% of the business enterprise. The disadvantaged owner must manage, operate, and control the managerial and daily operational functions of the firm. The owner’s personal net worth must be below $1,320,000. | C4: Arizona Department of Transportation | D4: FY 2024 | E4: 0.1255 | F4: Spending | G4: 0.079 | I4: =G4/E4 -> 0.62948207
A5: Arkansas | B5: If your firm is at least 51%-owned by a socially and economically disadvantaged individual(s) who also controls the firm. The disadvantaged owner is a U.S. Citizen or lawfully admitted permanent resident of the U.S.. The firm is a small business that meets the Small Business Administration’s (SBA’s) size standard and does not exceed $22.41 million in gross annual receipts. Is your firm organized as a for-profit business. | C5: Arkansas Department of Transportation | D5: FY 2021 | E5: 0.086 | F5: Participation | G5: 0.0772 | I5: 0.0772
A6: California | B6: Statewide: The firm is majority-owned (>51%) by minorities, women, and/or LGBT individuals The firm is managed and controlled on a daily basis by minorities, women, and/or LGBT individuals The firm is an independent business | C6: California Department of Transportation Disadvantaged Business Enterprise (DBE) FHWA-funded contracts | D6: FY 2020 | E6: 0.176 | F6: Participation | G6: 0.175 | I6: =G6/E6 -> 0.99431818
A7: Colorado | B7: For-profit small business concern as defined by the U.S. Small Business Administration (based upon NAICS) At least 51% owned by one or more individuals who are both socially and economically disadvantaged. Minorities and women are presumed to be socially disadvantaged. Management and daily business operations are controlled by one or more of the socially and economically disadvantaged individuals who own it. The disadvantaged owner(s) must have a personal net-worth of less than $1,320,000. Depending upon the nature of work performed, a firm (including its affiliates) must not have average annual gross receipts in excess of $22,410,000 ($52,470,000 for airport concessionaires in general with some exceptions). This size standard is for construction related work. Depending on the type of work the business performs, other lower size standards may apply. If state or local law requires the persons to have a particular license or other credential in order to own and/or control the firm, then the socially and economically disadvantaged owner(s) must possess the required license or credentials. | C7: Colorado Department of Transportation | D7: FY 2021 | E7: 0.1188 | F7: Participation | G7: 0.1184 | H7: =(457623760)+(424399) -> 458048159 | I7: =G7/E7 -> 0.996633
A8: Connecticut | B8: In order to qualify, the majority owner of the business must be a member of a socially or economically ‘disadvantaged’ group in the United States with legal residence. In addition, the owner must have proof of expertise in the given field of work, as well as maintain a personal net worth below $1.31 million. | C8: Connecticut Department of Transportation (need to update all amounts to 2022/2023 dollars if we include this state)* | D8: FY 2014* | E8: 0.107 | F8: Participation | G8: 0.133 | H8: 315029145 | I8: =G8/E8 -> 1.2429907
A9: Delaware | B9: Disadvantaged Business Enterprise (DBE) means a for-profit small business concern that is at least 51 percent owned by one or more individuals who are both socially and economically disadvantaged or, in the case of a corporation, in which 51 percent of the stock is owned by one or more such individuals; and whose management and daily business operations are controlled by one or more of the socially and economically disadvantaged individuals who own it. All DBE’s are small businesses by definition and thus qualify automatically to participate in the DelDOT Small Business Program. | C9: Delaware Department of Transportation DBE Program | D9: FY2022 | E9: 0.134 | F9: Participation | G9: 0.0961 | I9: =G9/E9 -> 0.71716418
A10: Florida | B10: Must be an existing "for-profit" business that is currently operational; Must meet the federal definition of a small business concern; Must be an independent business which does not depend on its relationships with another firm or firms. If it is a subsidiary of a corporation, the business must still operate in a self-sufficient manner; The qualifying owner(s) must meet the federal definition of "socially and economically disadvantaged" individuals; The qualifying owner(s) must own a minimum of 51% of the company; and have an investment in their company; The qualifying owner(s) cannot have a net worth that exceeds $2.047 Million The qualifying owner(s) must have day-to-day control of operations and possess an expertise in their work specialty. | C10: Florida Department of Transportation (FHWA specific) | D10: FY 2022 | E10: 0.1065 | F10: Participation | G10: 0.1266 | I10: =G10/E10 -> 1.1887324
A11: Georgia | B11: Hub communities are experiencing exceptional levels of population growth and economic development. Georgia's Chambers of Commerce continue to act as regional drivers, coalescing strategic partners and providing a table for critical conversations. | C11: Georgia Department of Commerce | D11: FY2024 | E11: 0.23 | F11: Participation | G11: 0.0564 | I11: =G11/E11 -> 0.24521739
A12: Hawaii | B12: Disadvantaged Business Enterprise (DBE) is a for-profit small business concern that is at least 51% owned and controlled by one or more U. S. citizens or permanent residents who are both socially and economically disadvantaged. Any individual in the following groups, members of which are rebuttably presumed to be socially and economically disadvantaged: “Black Americans,” “Hispanic Americans,” “Native Americans,” “Asian-Pacific Americans,” “Subcontinent Asian Americans,” Women; Any additional groups whose members are designated as socially and economically disadvantaged by the SBA, at such time as the SBA designation becomes effective. | C12: Disadvantaged Business Enterprise program administered by HI Dept of Transportation | D12: FY-2023 | E12: 0.23 | F12: Participation | G12: 0.1726 | I12: =G12/E12 -> 0.75043478
A13: Idaho | B13: To qualify as a DBE, firms must: Be existing, operational, and “for profit” Operate independently; or, for subsidiaries, operate self-sufficiently Meet the Federal definition of a “small business concern” In addition, firm owners must: Establish at least 51% real and substantial ownership Possess the power and expertise to control the daily operations and management of the firm Meet the Federal definition of “socially and economically disadvantaged” | C13: Overall Disadvantaged Business Enterprise Triennial Goal for the Federal Highway Administration | D13: FY-2023-2025 | E13: 0.1011 | G13: 0.0719 | I13: 0.7111
A14: Illinois | B14: A business that is at least 51% owned, controlled, and operated by individuals who are socially or economically disadvantaged, including minorities, women, persons with disabilities, and veterans. These businesses may qualify for state programs such as the Business Enterprise Program (BEP) and the Disadvantaged Business Enterprise (DBE) Program, which aim to increase access to government contracts and procurement opportunities. | C14: Business Enterprise Program | D14: FY-2023 | E14: 0.3 | F14: Spending | G14: 0.055 | I14: =G14/E14 -> 0.18333333
A15: Indiana | B15: In Indiana, a Historically Underutilized Business (HUB) refers to businesses that are at least 51% owned, operated, and controlled by minorities, women, or veterans, who have been historically underrepresented in state contracting. The Indiana Department of Administration’s Supplier Diversity Program promotes the inclusion of these businesses by setting participation goals in state contracts, including 7% for Minority Business Enterprises (MBE), 5% for Women Business Enterprises (WBE), and 3% for Veteran Business Enterprises (VBE) in construction | C15: IN Dept of Administration Division of Supplier Diversity | D15: FY-2024 | E15: 0.15 | F15: Spending | G15: 0.07 | I15: =G15/E15 -> 0.46666667
A16: Iowa | B16: the Disadvantaged Business Enterprise (DBE) program, overseen by the Iowa Department of Transportation (Iowa DOT), aims to ensure nondiscrimination in the award and administration of U.S. Department of Transportation-assisted contracts. The program seeks to create a level playing field for minority-owned, women-owned, and other socially and economically disadvantaged businesses to compete fairly for transportation-related projects | C16: Iowa Department of Transportation | D16: FY2024 | E16: 0.0572 | F16: Particpation | G16: 0.051 | I16: 0.977
A17: Kansas | B17: In Kansas, a Minority-Owned Business (MOB) is defined as a business that is at least 51% owned, operated, and controlled by one or more individuals from recognized minority groups, such as African American, Hispanic, Asian American, or Native American. A Women-Owned Business (WOB) is a business that is at least 51% owned, operated, and controlled by one or more women. A Veteran-Owned Business (VOB) is a business that is at least 51% owned, operated, and controlled by one or more veterans who have served in the U.S. military. These definitions are used to promote diversity in business ownership and ensure that historically underrepresented groups have opportunities to participate in state and federal contracting processes. | C17: Department of Transportation Authority | D17: FY2023 | E17: 0.23 | F17: Participation | G17: 0.2 | H17: 23800000 | I17: 0.8696
A18: Kentucky | B18: Whenever deemed by the CPO as in the best interests of the university, solicitations may include reserved points potential respondents certified as small and emerging business (R.S. 51:941), or a small entrepreneurship (R.S. 39:2006) or a veteran or service-connected disabled veteran- owned small entrepreneurship (R.S. 39:21). B. The CPO may waive the requirement of obtaining three or more quotes when purchases do not exceed $50,000 per transaction from a small entrepreneurship certified under either the Hudson or Veteran Initiative when price is determined to be reasonable, in their sole discretion. | C18: Kentucky Transportation Cabinet | D18: FY2021 | E18: 0.111 | F18: Spending | G18: 0.1171 | H18: 83234716 | I18: =G18/E18 -> 1.054955
A19: Louisiana | B19: Disadvantaged business enterprise orDBE means a for-profit small business concern: (1) That is at least 51 percent owned by one or more individuals who are both socially and eco nomically disadvantaged or, in the case of a corporation, in which 51 percent of the stock is owned by one or more such individuals; and (2) Whose management and daily business operations are controlled by one or more of the so cially and economically disadvantaged individuals who own it. | C19: Louisiana Department of Transportation and Development (LDOTD) | D19: FY 2022 | E19: 0.1 | F19: Participation | G19: 0.084 | I19: =G19/E19 -> 0.84
A20: Maine | B20: Your firm is at least 51% owned by a socially and economically disadvantaged individual(s) who also controls the firm. The disadvantaged owner is a U.S. citizen or lawfully admitted permanent resident of the U.S. Your firm is a small business that meets the Small Business Administration’s (SBA’s) size standard and does not exceed $30.72 million in gross annual receipts. (Average over 3 previous fiscal years) Your firm is a small ACDBE business that meets the Small Business Administration’s (SBA’s) size standard and does not exceed $56.42 million in gross annual receipts (Average over 5 previous fiscal years) Your firm is organized as a for-profit business. Your firm must be able to provide a service or product to participate in DOT-assisted projects. Your personal net worth cannot exceed $1.32 million. | C20: Maine Department of Economic and Community Development | D20: FY 2022 | E20: 0.0143 | F20: Participation | G20: 0.0101 | I20: 0.7062
A21: Maryland | B21: Business is independently owned and operated. Business is not a subsidary of another business. Business is not dominant in field of operation.The wholesale operations of the business did not employ more than 50 persons in its most recently completed 3 fiscal years | C21: Maryland Department of Commerce | D21: FY 2023 | E21: 0.2604 | F21: Participation | G21: 0.296 | H21: 18700000 | I21: 1.1367
A22: Massachusetts | B22: The Supplier Diversity Program (SDP) encourages the award of state contracts in a way that strengthens and increases business opportunities for Minority Business Enterprises (MBEs), Women Business Enterprises (WBEs), Service-Disabled Veteran Business Enterprises (SDVOBEs),Veteran Business Enterprises (VBEs), Lesbian, Gay, Bisexual, and Transgender Business Enterprises (LGBTBEs); and Disability-Owned Business Enterprises (DOBEs). | C22: Executive Office of Economic Development | D22: FY 2023 | E22: 0.054 | F22: Participation | G22: 0.07 | I22: =G22/E22 -> 1.2962963
A23: Michigan | B23: In establishing ownership, the MUCP is required by 49 CFR § 26.69 to consider all the facts in the record, viewed as a whole. To be an eligible DBE, a firm must be at least 51 percent owned by a socially and economically disadvantaged individual(s). To establish ownership, the socially and economically disadvantaged owner(s) must have made a "real and substantial" contribution to acquire their ownership interest in the firm. All applicants for certification shall be required to establish the source of their contribution(s) to acquire their ownership interest. | C23: Michigan DOT DBE program | D23: FY 2023 | E23: 0.0956 | F23: Participation | G23: 0.075 | I23: 0.7845
A24: Minnesota | B24: To be certified as a Targeted Group small business, the business must be at least 51% owned by a woman, racial minority, or person with a substantial physical disability. In addition, the business must be operated and controlled on a day-to-day as well as long-term basis by the qualifying owner. In other words, ownership is not enough; operational control is also required. | C24: Minnesota Department of Employment and Economic Development | D24: FY 2022 | E24: 0.126 | F24: Participation | G24: 0.082 | I24: 0.6833
A25: Mississippi | B25: a) The firm must be at least 51% owned by one or more socially and economically disadvantaged individuals. b) The firm must be an independent business, and one or more of the socially and economically disadvantaged owners must control its management and daily operations. c) The owner must hold the highest office. d) Must own necessary equipment and have necessary personnel to do the work. e) Only existing for-profit “Small Business Concerns,” as defined by the Small Business Act and Small Business Administration (SBA) regulations may be certified. DBE applicants are first subject to the applicable small business size standards of the SBA. Second, the average annual gross receipts for the firm (including its affiliates) over the previous three fiscal years must not exceed U.S. DOT’s cap of $22,410,000 Million. | C25: Mississippi Development Authority | D25: FY 2023 | E25: 0.1 | F25: Participation | G25: 0.08 | I25: 0.8
A26: Missouri | B26: As established by the Small Business Administration, the business must have three-year average gross receipts not to exceed $23.98 million. Socially and Economically Disadvantaged people are defined as Women, black Americans, Hispanic Americans, native Americans, Asian-Pacific Americans, subcontinent Asian-Americans, other groups designated by SBA. Others able to prove to be socially and economically disadvantaged as outlined in the regulation. Participants must demonstrate they are a member of an eligible group. Personal Net Worth of Owner is not to exceed $1.32 million. Ownership and Control is defined as 51% majority owner must prove ownership and control of the firm. Other Rules Affecting Certification include that the company must not exhibit pattern of evading or subverting the intent of the DBE program. | C26: Missouri Department of Economic Development | D26: FY 2023 | E26: 0.15 | F26: Participation | G26: 0.12 | I26: 0.75
A27: Montana | B27: The majority owner(s) must have been subjected to racial or ethnic prejudice or cultural bias within American society because of his or her identity as a member of groups without regard to his or her individual qualities. The social disadvantage must stem from circumstances beyond the individual’s control. The following groups are rebuttably presumed to be disadvantaged: Black Americans, Hispanic Americans, Native Americans, Asian-Pacific Americans, Subcontinent Asian Americans, Women, and Any additional groups whose members are designated as socially and economically disadvantaged by the SBA, at such time as the SBA designation becomes effective. Business Size: A firm (including affiliates) must be a small business as defined by SBA standards. Find the table of size standards based on your business’s work type (NAICS Code) here. Personal Net Worth: The majority owner(s) of the company must have a personal net worth under $2,047,000 (excluding equity in applicant/certified business, primary residence, and retirement accounts). For-Profit: Firm must be organized for profit. Not-for-profit organizations are not eligible. Citizenship: Majority owner(s) must be a citizen (or lawfully admitted permanent resident) of the United States. | C27: Montana Department of Commerce | D27: FY 2020 | E27: 0.065 | F27: Participation | G27: 0.081 | I27: =G27/E27 -> 1.2461538
A28: Nebraska | B28: Disadvantaged Business Enterprise or DBE - A for-profit small business concern: (a) That is at least 51 percent owned by one or more individuals who are both socially and economically disadvantaged or, in the case of a corporation, in which 51 percent of the stock is owned by one or more such individuals; and (b) Whose management and daily business operations are controlled by one or more of the socially and economically disadvantaged individuals who own it. (See 49 CFR part 26.67) | C28: Nebraska Department of Transportation FHWA DBE Program | D28: FY2022 | E28: 0.0581 | F28: Particiapation | G28: 0.046 | I28: =G28/E28 -> 0.79173838
A29: Nevada | B29: A Disadvantaged Business Enterprise, also known as a DBE, is a small for-profit business concern that is 51% owned by a designated group, such as a Woman, Veteran, LGBTQ, or Minority. To ensure Nevada is a premier business location for all businesses, the Nevada Legislature passed Assembly 436 in 2017. This legislation ensures that it's easy to obtain information concerning programs to provide financing for small businesses, in addition to information concerning the process by which the business may become certified as a disadvantaged business enterprise for the purposes of 49 C.F.R. § 26.5 or a program to provide financing for disadvantaged business enterprises. | C29: Nevada Department of Transportation DBE Program, FHWA-funded contracts | D29: FY2021 | E29: 0.222 | F29: Particiapation | G29: 0.0822 | H29: =0.0822*272700000 -> 22415940 | I29: =G29/E29 -> 0.37027027
A30: New Hampshire | B30: In order to qualify as a DBE/ACDBE, all companies must meet the following requirements: The owner and the business company have to have established their principal office in New Hampshire. The owner must be a member of a socially and economically disadvantaged group. This means owners who are citizens of the United States, and/or lawfully admitted permanent residents, and are: Black, Hispanic, Native Americans, Asian-Pacific Islanders, Subcontinent Asians, or women regardless of race. The business must be owned, at least 51%, by one or more individuals who are considered members of a socially and economically disadvantaged group. The disadvantaged owner(s) must control the company's management and daily operations. A disadvantaged owner(s) personal net worth cannot exceed $2,047,000 (excluding ownership interest in the firm and the equity in his/her primary residence). For DBEs, the company must not exceed $30.72 million in gross annual receipts and meet the Small Business Administration's Size Standard requirements | C30: New Hampshire Department of Transportation DBE Program | D30: FY2022 | E30: 0.0482 | F30: Participation | G30: 0.0255 | I30: =G30/E30 -> 0.52904564
A31: New Jersey | B31: To qualify for the 8(a) program, businesses must meet the following eligibility criteria: Be a small business Not have previously participated in the 8(a) program Be at least 51% owned and controlled by U.S. citizens who are socially and economically disadvantaged Have a personal net worth of $850 thousand or less, adjusted gross income of $400 thousand or less, and assets totaling $6.5 million or less Demonstrate good character Demonstrate the potential for success such as having been in business for two years | C31: New Jersey department of Transportation DBE Program | D31: FY2022 | E31: 0.1323 | F31: Participation | G31: 0.1213 | I31: =G31/E31 -> 0.91685563
A32: New Mexico | B32: "historically underutilized business" means a legally recognized for-profit business organization, corporation, sole proprietorship, partnership or joint venture that has applied for and received a valid historically underutilized business certificate issued by the taxation and revenue department certifying that: (1) it has an average gross revenue for the preceding three calendar years that does not exceed five million dollars ($5,000,000), as reported to the taxation and revenue department, or an average number of employees in New Mexico for the preceding three calendar years that does not exceed fifty; (2) it is a "resident business" as certified by the taxation and revenue department pursuant to Section 13-1-22 NMSA 1978; and (3) as certified by the taxation and revenue department, more than fifty percent of the business is owned by women or persons who are members of one or more of the following communities of color: African American, Latino or Hispanic, Asian, Pacific Islander, Native American or Alaska Native; | C32: DBE program through New Mexico Department of Transporation | D32: FY2021-2023 | E32: 0.123 | F32: Participation | G32: 0.2256 | I32: =G32/E32 -> 1.8341463
A33: New York | B33: Minority-Owned Business Enterprise (MBE): Under Article 15-A of the Executive Law, an MBE is a business enterprise in which at least fifty-one percent (51%) is owned, operated and controlled by citizens or permanent resident aliens who are meeting the ethnic definitions listed below: Black, Hispanic, Asian-Pacific, Asian-Indian Subcontinent, Native American or Alaskan Native | C33: New York Division of Minority and Women’s Business Development | D33: FY2023 | E33: 0.3 | F33: Spending | G33: 0.3221 | H33: 2822296207 | I33: =G33/E33 -> 1.0736667
A34: North Carolina | B34: At least fifty-one percent (51%) of the business is owned by one or more persons who are members of at least one of the following groups: Black, Hispanic, Asian American, American Indian, Female, Disabled, or Disadvantaged. The management and daily business operations are controlled by one or more owners of the business who are members of at least one of the groups set forth in the groups above. | C34: NC Department of Administration, Office for Historically Underutilized Businesses | D34: FY2022 | E34: 0.1 | F34: Spending | G34: 0.0859 | H34: 1050846150 | I34: =G34/E34 -> 0.859
A35: North Dakota | B35: **Program specific to federally-aided highway construction projects.** An individual must own 51% or more of a “small business” and establish that they are socially and economically disadvantaged. A disadvantaged owner seeking certification must possess the power to direct or cause the direction of the management and policies of the firm. The owner must also have an overall understanding of managerial and technical competency and experience directly related to the type of business in which the firm is engaged. Certain groups are presumed socially disadvantaged by the U.S. Small Business Administration including women, Black Americans, Hispanic Americans, Native Americans, Asian-Pacific Americans, Subcontinent Asian-Pacific Americans. | C35: DBE program through ND Department of Transportation | D35: FY2022 | E35: 0.0466 | F35: Participation | G35: 0.0641 | I35: =G35/E35 -> 1.3755365
A36: Ohio | B36: (G) "Economically Disadvantaged Business" means a business (including its affiliates) is at least fifty-one per cent owned and controlled by a socially and economically disadvantaged individual(s) and the size of the business does not exceed the definition of a "small business" as defined by the United States small business administration (SBA) in 13 C.F.R 121.201 (2020) and calculated in accordance with 13 C.F.R 121.101 to 121.107 (2020); (1) To be a "small business" as defined by the SBA standards, only one main North American industry classification system (NAICS) code is used to determine the company's size standard. The main NAICS code (the code in which the majority of the company's gross receipts are generated) as identified by the Ohio department of administrative services, equal opportunity division (DAS/EOD) at the time of certification or recertification is the only NAICS code used to determine a business's size standard. (H) "Economically Disadvantaged Individual" means an individual(s) whose ability to compete in the free enterprise system has been impaired due to diminished capital and credit opportunities as compared to others in the same or similar business(es) that are not economically disadvantaged. Economic disadvantage is based on 13 C.F.R. | C36: Department of Administrative Services, Equal Opportunity Division | D36: FY2020 | E36: 0.15 | F36: Participation | G36: 0.215 | H36: 298800000 | I36: 1.4333
A37: Oklahoma | B37: NMSDC and its affiliates solicit major corporations and large companies to do more purchasing from minority-owned businesses and provide a “Minority Business Enterprise” (MBE) certification to assist in identifying eligible minority-owned businesses. To qualify for certification, the minority business owner must: • Be from one of the following racial minority/ethic groups: African American/Black, Native American, Hispanic/ Latino American, Asian-Pacific American and Asian-Indian American; • Hold 51% or more of the ownership of the business, • Have full control of its operations and management. | C37: Oklahoma Department of Transportation and Disadvantaged Business Enterprise | D37: FY2024 | E37: 0.0805 | F37: Spending | G37: 0.1876 | H37: 90371156 | I37: =G37/E37 -> 2.3304348
A38: Oregon | B38: small businesses that are at least 51% owned by: Minorities: Blacks, Hispanics, Native Americans, Asian-Pacific Americans and Subcontinent Asian Americans; Women; Other individuals on a case-by-case basis. | C38: Oregon DOT FHWA | D38: FY2021 | E38: 0.154 | F38: Participation | G38: 0.1252 | I38: =G38/E38 -> 0.81298701
A39: Pennsylvania | B39: Woman-owned business, minority-owned business or veteran-owned business” - Diverse and disadvantaged businesses. | C39: Department of General Services: Bureau of Small Business Opportunities | D39: FY2024 | E39: 0.1101 | F39: Allocation Percentage | G39: 0.112 | H39: 275090953 | I39: =G39/E39 -> 1.017257
A40: Rhode Island | B40: 51% owned and operated by socially and economically disadvantaged individuals. This often includes minority-owned, women-owned, veteran-owned, and other disadvantaged businesses. | C40: Department of Administration; Rhode Island Minority Business Enterprise Compliance Office; Division of Diversity, Equity, and Inclusion | D40: FY2024 | E40: 0.15 | F40: Participation | G40: 0.104 | I40: =G40/E40 -> 0.69333333
...

Sheet Sheet1

Sheet Data Visualization
A1: States | B1: Success (%) | C1: Spending ($) | R1: States | S1: Spending ($USD)
A2: Alabama | B2: ='Full Spreadsheet'!I2 -> 0.87976879 | C2: ='Full Spreadsheet'!H2 -> 0 | R2: Colorado | S2: 458048159
A3: Alaska | B3: ='Full Spreadsheet'!I3 -> 3.0533333 | C3: ='Full Spreadsheet'!H3 -> 0 | R3: Connecticut | S3: 315029145
A4: Arizona | B4: ='Full Spreadsheet'!I4 -> 0.62948207 | C4: ='Full Spreadsheet'!H4 -> 0 | R4: Kansas | S4: 23800000
A5: Arkansas | B5: ='Full Spreadsheet'!I5 -> 0.0772 | C5: ='Full Spreadsheet'!H5 -> 0 | R5: Kentucky | S5: 83234716
A6: California | B6: ='Full Spreadsheet'!I6 -> 0.99431818 | C6: ='Full Spreadsheet'!H6 -> 0 | R6: Maryland | S6: 18700000
A7: Colorado | B7: ='Full Spreadsheet'!I7 -> 0.996633 | C7: ='Full Spreadsheet'!H7 -> 458048159 | R7: Nevada | S7: 22415940
A8: Connecticut | B8: ='Full Spreadsheet'!I8 -> 1.2429907 | C8: ='Full Spreadsheet'!H8 -> 315029145 | R8: New York | S8: 2822296207
A9: Delaware | B9: ='Full Spreadsheet'!I9 -> 0.71716418 | C9: ='Full Spreadsheet'!H9 -> 0 | R9: North Carolina | S9: 1050846150
A10: Florida | B10: ='Full Spreadsheet'!I10 -> 1.1887324 | C10: ='Full Spreadsheet'!H10 -> 0 | R10: Ohio | S10: 298800000
A11: Georgia | B11: ='Full Spreadsheet'!I11 -> 0.24521739 | C11: ='Full Spreadsheet'!H11 -> 0 | R11: Oklahoma | S11: 90371156
A12: Hawaii | B12: ='Full Spreadsheet'!I12 -> 0.75043478 | C12: ='Full Spreadsheet'!H12 -> 0 | R12: Pennsylvania | S12: 275090953
A13: Idaho | B13: ='Full Spreadsheet'!I13 -> 0.7111 | C13: ='Full Spreadsheet'!H13 -> 0 | R13: South Carolina | S13: 58991000
... A22: Massachusetts | B22: ='Full Spreadsheet'!I22 -> 1.2962963 | C22: ='Full Spreadsheet'!H22 -> 0 | R22: Wyoming | S22: 874740692
A23: Michigan | B23: ='Full Spreadsheet'!I23 -> 0.7845 | C23: ='Full Spreadsheet'!H23 -> 0
A24: Minnesota | B24: ='Full Spreadsheet'!I24 -> 0.6833 | C24: ='Full Spreadsheet'!H24 -> 0
A25: Mississippi | B25: ='Full Spreadsheet'!I25 -> 0.8 | C25: ='Full Spreadsheet'!H25 -> 0
A26: Missouri | B26: ='Full Spreadsheet'!I26 -> 0.75 | C26: ='Full Spreadsheet'!H26 -> 0
A27: Montana | B27: ='Full Spreadsheet'!I27 -> 1.2461538 | C27: ='Full Spreadsheet'!H27 -> 0
A28: Nebraska | B28: ='Full Spreadsheet'!I28 -> 0.79173838 | C28: ='Full Spreadsheet'!H28 -> 0
A29: Nevada | B29: ='Full Spreadsheet'!I29 -> 0.37027027 | C29: ='Full Spreadsheet'!H29 -> 22415940
A30: New Hampshire | B30: ='Full Spreadsheet'!I30 -> 0.52904564 | C30: ='Full Spreadsheet'!H30 -> 0
A31: New Jersey | B31: ='Full Spreadsheet'!I31 -> 0.91685563 | C31: ='Full Spreadsheet'!H31 -> 0
A32: New Mexico | B32: ='Full Spreadsheet'!I32 -> 1.8341463 | C32: ='Full Spreadsheet'!H32 -> 0
A33: New York | B33: ='Full Spreadsheet'!I33 -> 1.0736667 | C33: ='Full Spreadsheet'!H33 -> 2822296207
A34: North Carolina | B34: ='Full Spreadsheet'!I34 -> 0.859 | C34: ='Full Spreadsheet'!H34 -> 1050846150
... A51: Wyoming | B51: ='Full Spreadsheet'!I51 -> 1.189 | C51: ='Full Spreadsheet'!H51 -> 874740692

Sheet Heatmap

Sheet Oklahoma
A1: Total Spending | B1: DBE Spending | C1: Goal | D1: Attainment | E1: Proportion | F1: Goal (weighted) | G1: Attainment (weighted)
A2: 866800 | B2: 15100 | C2: 0.02 | D2: 0.0174 | E2: =A2/A$313 -> 0.0018042044 | F2: =C2*E2 -> 3.6084087e-05 | G2: =D2*E2 -> 3.1393156e-05
A3: 1080115 | B3: 345600 | C3: 0.08 | D3: 0.32 | E3: =A3/A$313 -> 0.0022482097 | F3: =C3*E3 -> 0.00017985678 | G3: =D3*E3 -> 0.00071942712
A4: 980250 | B4: 286500 | C4: 0.08 | D4: 0.2923 | E4: =A4/A$313 -> 0.0020403453 | F4: =C4*E4 -> 0.00016322763 | G4: =D4*E4 -> 0.00059639294
A5: 1209370 | B5: 18738 | C5: 0.015 | D5: 0.0155 | E5: =A5/A$313 -> 0.0025172481 | F5: =C5*E5 -> 3.7758721e-05 | G5: =D5*E5 -> 3.9017345e-05
A6: 1672515 | B6: 292190 | C6: 0.03 | D6: 0.1747 | E6: =A6/A$313 -> 0.0034812631 | F6: =C6*E6 -> 0.00010443789 | G6: =D6*E6 -> 0.00060817667
A7: 2730217.5 | B7: 67985.04 | C7: 0.06 | D7: 0.0249 | E7: =A7/A$313 -> 0.0056828223 | F7: =C7*E7 -> 0.00034096934 | G7: =D7*E7 -> 0.00014150228
A8: 148981.6 | B8: 9000 | C8: 0.06 | D8: 0.0604 | E8: =A8/A$313 -> 0.00031009836 | F8: =C8*E8 -> 1.8605901e-05 | G8: =D8*E8 -> 1.8729941e-05
A9: 706188.45 | B9: 120202 | C9: 0.06 | D9: 0.1702 | E9: =A9/A$313 -> 0.0014698988 | F9: =C9*E9 -> 8.8193929e-05 | G9: =D9*E9 -> 0.00025017678
A10: 2257328.6 | B10: 165865.02 | C10: 0.06 | D10: 0.0735 | E10: =A10/A$313 -> 0.0046985258 | F10: =C10*E10 -> 0.00028191155 | G10: =D10*E10 -> 0.00034534164
A11: 630896.73 | B11: 59877.08 | C11: 0.06 | D11: 0.0949 | E11: =A11/A$313 -> 0.0013131826 | F11: =C11*E11 -> 7.8790953e-05 | G11: =D11*E11 -> 0.00012462102
A12: 1137800 | B12: 609100 | C12: 0.08 | D12: 0.5353 | E12: =A12/A$313 -> 0.0023682784 | F12: =C12*E12 -> 0.00018946227 | G12: =D12*E12 -> 0.0012677394
A13: 694624 | B13: 35511 | C13: 0.05 | D13: 0.0511 | E13: =A13/A$313 -> 0.0014458279 | F13: =C13*E13 -> 7.2291397e-05 | G13: =D13*E13 -> 7.3881808e-05
... A312: 4301335.8 | B312: 756437.59 | C312: 0.16 | D312: 0.1759 | E312: =A312/A$313 -> 0.0089530328 | F312: =C312*E312 -> 0.0014324853 | G312: =D312*E312 -> 0.0015748385
A313: =SUM(A2:A312) -> 4.8043338e+08 | B313: =SUM(B2:B312) -> 90371156 | F313: =SUM(Oklahoma[Goal (weighted)]) -> 0.080543041 | G313: =SUM(Oklahoma[Attainment (weighted)]) -> 0.18758647
F314: =Oklahoma[[#Totals],[Goal (weighted)]] -> 0.080543041 | G314: =Oklahoma[[#Totals],[Attainment (weighted)]] -> 0.18758647

Sheet Sources
A1: States | B1: Sources Used
A2: Alabama | B2: https://www.aamu.edu/about/administrative-offices/bulldog-transportation-service/_documents/aamu-dbe-goal-methodology-document.pdf | C2: https://www.urban.org/policy-centers/cross-center-initiatives/state-and-local-finance-initiative/projects/state-fiscal-briefs/alabama#:~:text=Alabama%20enacted%20its%20FY2024%20budget,%2C%20bonds%2C%20and%20federal%20funds.
A3: Alaska | B3: https://dot.alaska.gov/cvlrts/aucp.shtml | C3: https://www.urban.org/policy-centers/cross-center-initiatives/state-and-local-finance-initiative/projects/state-fiscal-briefs/alaska#:~:text=According%20to%20the%20National%20Association,%2C%20bonds%2C%20and%20federal%20funds. | D3: https://dot.alaska.gov/cvlrts/pdfs/Alaska-DOTPF-FTA-FFY2021-2023-DBE-Goal-Methodology.pdf | E3: https://dot.alaska.gov/cvlrts/pdfs/Alaska-DOTPF-FHWA-Disadvantaged-Business-Enterprise-Program-Plan-2024.pdf | F3: https://www.census.gov/quickfacts/fact/table/AK/PST045223
A4: Arizona | C4: https://www.urban.org/policy-centers/cross-center-initiatives/state-and-local-finance-initiative/projects/state-fiscal-briefs/arizona#:~:text=Arizona%20enacted%20its%20FY%202024,31%2C%202026.
A5: Arkansas | B5: http://www.ahtd.ar.gov/dbe/DBE%20Uniform%20Certification%20Application2.pdf | C5: https://www.ardot.gov/wp-content/uploads/2022/06/2023-2025-Draft-DBE-Goal-Report.pdf | D5: https://www.urban.org/policy-centers/cross-center-initiatives/state-and-local-finance-initiative/projects/state-fiscal-briefs/arkansas#:~:text=Per%20the%20US%20Census%20Bureau,university%20tuition%20and%20highway%20tolls.
A6: California | B6: https://supplier.coupa.com/certifications/dbe-certifications-in-california/ https://dot.ca.gov/programs/local-assistance/local-civil-compliance/disadvantaged-business-enterprise-dbe#:~:text=Caltrans%20is%20required%20under%2049,the%20Caltrans%20DBE%20Program%20Plan https://dot.ca.gov/-/media/dot-media/programs/civil-rights/documents/disparity-study/caltrans-2022-2024-proposed-dbe-goal-and-methodology-a11y.pdf
A7: Colorado | B7: Overall Annual DBE Goal for Highway Design and Construction
A8: Connecticut
A9: Delaware | B9: https://deldot.gov/Business/dbe/contentFolder/pdfs/dbeProgram.pdf?cache=1739994787952 https://deldot.gov/Business/dbe/index.shtml https://deldot.gov/Business/dbe/contentFolder/pdfs/dbeGoalMethodology.pdf?cache=1739994894399
A10: Florida | B10: https://www.fdot.gov/equalopportunity/dbecertification.shtm https://dms-media.ccplatform.net/content/download/162582/file/Dept%20of%20Transportation.pdf?utm_source=chatgpt.com | C10: https://www.urban.org/policy-centers/cross-center-initiatives/state-and-local-finance-initiative/projects/state-fiscal-briefs/florida | D10: https://www.fdot.gov/equalopportunity/civilrightsprograms.shtm
A11: Georgia | B11: http://doas.ga.gov/state-purchasing
A12: Hawaii | B12: https://defenseeconomy.hawaii.gov/small-business/
A13: Idaho | B13: DBE_Goal_Methodology_Proposed.pdf
A14: Illinois
A15: Indiana
A16: Iowa
A17: Kansas | B17: https://www.kcata.org/documents/uploads/KCATA1827DBEProgram.pdf? | C17: https://www.kslegislature.gov/li_2024/b2023_24/measures/documents/sb464_00_0000.pdf | D17: https://www.kslegislature.gov/li_2024/b2023_24/measures/hb2184/ | E17: https://www.urban.org/policy-centers/cross-center-initiatives/state-and-local-finance-initiative/projects/state-fiscal-briefs/kansas#:~:text=According%20to%20NASBO%2C%20Kansas's%20recent,%247.3%20billion%2F%2421.8%20billion
A18: Kentucky
A19: Louisiana | B19: https://www.lsu.edu/administration/ofa/procurement /index.php
A20: Maine | B20: https://www.mainedbe.com/become-certified/ https://www1.maine.gov/mdot/lpa/docs/certification/2024/DBEPresentation_Oct2024.pdfhttps://www.maine.gov/mdot/civilrights/docs/dbe/2020/2020-2022%20FTA%20Goal%20Methodology.pdf
A21: Maryland | B21: https://mgaleg.maryland.gov/2024RS/bills/sb/sb0154f.pdf https://www.roads.maryland.gov/mdotsha/pages/Index.aspx?PageId=435 https://dbm.maryland.gov/budget/Pages/operbudget/2023-FiscalDigest.aspx https://mgaleg.maryland.gov/pubs/budgetfiscal/2023fy-budget-docs-operating-T00-Department-of-Commerce.pdf
A22: Massachusetts | B22: https://www.mass.gov/doc/dbe-goal-for-fta-assisted-contracts-ffy2022-2024/download https://malegislature.gov/Budget/FY2023/FinalBudget
A23: Michigan | B23: Executive Directive 2019 - 08 https://www.michigan.gov/mdot/-/media/Project/Websites/MDOT/Programs/DBE/FY2023-FY2025-Goals-Notice.pdf?rev=457b65b5da424e9faab8a21c65d00580&hash=FC8C3DA87883A5732E1E3F4D8F12AAAF https://www.michigan.gov/budget/-/media/Project/Websites/budget/Fiscal/Current-Fiscal-Year-Budget/FY-2023-Enacted-Summary.pdf?rev=a8c608c483a3476ca1041c23889b075d&hash=36CDB27D76C1F20427E1449D28D10BF3
A24: Minnesota | B24: https://mn.gov/admin/business/vendor-info/oep/sbcp/tg/ https://mn.gov/admin/business/vendor-info/oep/spend/ https://www.usaspending.gov/state/minnesota/2022 https://www.usaspending.gov/state/minnesota/2022
A25: Mississippi | B25: https://mdot.ms.gov/documents/Civil%20Rights/Programs/DBE/MS%20Unified%20Certification%20Program%20Letter.pdf https://www.lbo.ms.gov/PublicReports/GetBudgetRequestDetailReport/0?report=Intro&fiscalYear=2023
A26: Missouri | B26: DBE Frequently Asked Questions | Missouri Department of Transportation https://oa.mo.gov/budget-planning/budget-information/2023-budget-information https://oa.mo.gov/sites/default/files/FY_2023_EB_Elementary_and_Secondary_Education.pdf
A27: Montana | B27: https://www.mdt.mt.gov/business/contracting/civil/certification.aspx https://mdt.mt.gov/other/webdata/external/civilrights/dbe/FTA_DBE_Goal.pdf https://mdt.mt.gov/other/webdata/external/civilrights/dbe/FHWA_DBE_Goal.pdf
A28: Nebraska | B28: https://nebraskalegislature.gov/FloorDocs/106/PDF/Intro/LB1218.pdf http://www.nebraskatransportation.org/letting/DBE/DBE%20Program.pdf https://dot.nebraska.gov/media/utaliqat/ndot_fhwa_dbe_goal_fy2024-2026.pdf
A29: Nevada | B29: https://www.nvsilverflume.gov/home/nevadaDisadvantagedBusinessResources https://epubs.nsla.nv.gov/statepubs/epubs/352269-2021.pdf
A30: New Hampshire | B30: https://www.dot.nh.gov/doing-business-nhdot/office-federal-compliance/disadvantaged-business-enterprise-program https://mm.nh.gov/files/uploads/dot/remote-docs/dbe-goal-and-methodology-plan.pdf
... A35: North Dakota | B35: https://www.dot.nd.gov/sites/www/files/documents/civil-rights/DBE-Program-Guide.pdf https://www.dot.nd.gov/about-nddot/civil-rights/disadvantaged-business-enterprise-dbe-program
A36: Ohio | B36: https://codes.ohio.gov/ohio-administrative-code/rule-123:2-14-01#:~:text=(G)%20%22Economically%20Disadvantaged%20Business,is%20based%20on%2013%20C.F.R. | C36: https://ohiombe.com/archives/15728?utm_source=chatgpt.com
A37: Oklahoma | B37: https://www.okcommerce.gov/wp-content/uploads/Minority-Business-Certification-Programs.pdf https://oklahoma.gov/content/dam/ok/en/odot/civil-rights/dbe-methodology/FFY23-FFY25%20Overall%20Goal%20Methodology%20Final.pdf https://oklahoma.gov/content/dam/ok/en/odot/civil-rights/commitment-reports/pre-construction-dbe-reports/2024/November%202024.pdf
A38: Oregon | B38: https://www.orapexaccelerator.org/hub-zone-small-business | C38: https://www.oregon.gov/ohcs/homeownership/Documents/HO%20MWESB%20SDVBE%20FAQs%209.2024.pdf?utm_source=chatgpt.com
A39: Pennsylvania | B39: https://www.legis.state.pa.us/CFDOCS/Legis/PN/Public/btCheck.cfm?billbody=H&billnbr=0029&billtyp=B&pn=0010&sessInd=0&sessYr=2025&txtType=PDF&utm_source=chatgpt.com https://portal.ct.gov/dot/-/media/dot/ooe/unifiedcertificationprogrammanualattachmentsfinalpdf.pdf?rev=d2d794528d084e44aacc31bf81e6f3e1&hash=355B30B4446F88B5F40BF3AB45D3F305 | C39: https://www.pahousegop.com/budget2024?utm_source=chatgpt.com
A40: Rhode Island | B40: https://dedi.ri.gov/media/1001/download?language=en https://dedi.ri.gov/
A41: South Carolina | B41: https://www.scstatehouse.gov/sess117_2007-2008/bills/3902.doc https://publish-p131054-e1276845.adobeaemcloud.com/content/dam/scdot-legacy/business/pdf/businessdevelop/FFY_21-2023_Goal_Methodology_FHWA.pdf https://publish-p131054-e1276845.adobeaemcloud.com/content/dam/scdot-legacy/business/pdf/businessdevelop/FFY_21-2023_Goal_Setting_Methodology.pdfhttps://publish-p131054-e1276845.adobeaemcloud.com/content/dam/scdot-legacy/business/pdf/businessdevelop/FFY_21-2023_Goal_Setting_Methodology.pdf | C41: https://publish-p131054-e1276845.adobeaemcloud.com/content/dam/scdot-legacy/business/pdf/businessdevelop/FFY_21-2023_Goal_Setting_Methodology.pdf
A42: South Dakota
A43: Tennessee | B43: https://www.tn.gov/generalservices/procurement/central-procurement-office--cpo-/go-dbe.html?utm_source=chatgpt.com https://www.tn.gov/content/dam/tn/tdot/civilrights/small-business/2021%20-%202023%20DBE%20Goal%20FHWA%20Final%20Approved_SIGNED.pdf | C43: https://www.tn.gov/content/dam/tn/generalservices/documents/cpo/godbe/events-and-publications/publications/annual-report/Annual_Report_from_FY20-21_FINAL_on_12-22-21.pdf?utm_source=chatgpt.com
A44: Texas | B44: https://comptroller.texas.gov/purchasing/vendor/hub/disparity/ | C44: https://comptroller.texas.gov/data/purchasing/hub/fy24/hubreportfy24a.pdf (page 1 executive summary)
...
